<?xml version="1.0" encoding="utf-8"?>
<testsuites>
    <testsuite name="pytest" errors="0" failures="2" skipped="1" tests="7" time="0.052" timestamp="2023-01-11T13:04:33.083583" hostname="Elenas-MacBook-Pro.local">
        <testcase classname="tests_temp.test_first" name="test_first_one" time="0.001" />
        <testcase classname="tests_temp.test_first" name="test_first_two" time="0.000" />
        <testcase classname="tests_temp.test_first" name="test_first_failed" time="0.000">
            <failure message="AssertionError: This test is intentionally failed&#10;assert False">def test_first_failed():
&gt;       assert False, 'This test is intentionally failed'
E       AssertionError: This test is intentionally failed
E       assert False

tests_temp/test_first.py:11: AssertionError</failure>
        </testcase>
        <testcase classname="tests_temp.test_second" name="test_second_one" time="0.000" />
        <testcase classname="tests_temp.test_second" name="test_second_two" time="0.000" />
        <testcase classname="tests_temp.test_second" name="test_second_three" time="0.000">
            <skipped type="pytest.skip" message="unconditional skip">/Users/elenakulgavaya/work/idiomatic/formulabase/tests_temp/test_second.py:12: unconditional skip</skipped>
        </testcase>
        <testcase classname="tests_temp.suite_one.test_failed" name="test_failure" time="0.000">
            <failure message="AssertionError: Unexpected test result&#10;assert False">def test_failure():
&gt;       assert False, 'Unexpected test result'
E       AssertionError: Unexpected test result
E       assert False

tests_temp/suite_one/test_failed.py:3: AssertionError</failure>
        </testcase>
    </testsuite>
</testsuites>